pyunitwizard.\_private\_tools.exceptions.BadCallError
=====================================================

.. currentmodule:: pyunitwizard._private_tools.exceptions

.. autoexception:: BadCallError